/**
 * Error Boundary Coverage Gaps Tests
 *
 * Tests error boundary coverage gaps and error handling scenarios.
 * Ensures the application handles errors gracefully and provides good UX.
 */

import React from 'react';
import { render, screen, fireEvent, waitFor } from '@testing-library/react';
import { jest } from '@jest/globals';

// Mock the logger
jest.mock('@/clientLogger', () => ({
    createLogger: () => ({
        info: jest.fn(),
        error: jest.fn(),
        warn: jest.fn(),
        debug: jest.fn()
    })
}));

// Import after mocks
import { ErrorBoundary } from '@/components/ErrorBoundary';

// Component that throws an error
const ErrorThrowingComponent: React.FC<{ shouldThrow?: boolean }> = ({ shouldThrow = true }) => {
    if (shouldThrow) {
        throw new Error('Test error from component');
    }
    return <div data-testid="normal-component">Normal component</div>;
};

// Wrapper component that can change throwing behavior
const TestWrapper: React.FC<{ shouldThrow: boolean }> = ({ shouldThrow }) => {
    return <ErrorThrowingComponent shouldThrow={shouldThrow} />;
};

// Component that throws different types of errors
const DifferentErrorTypesComponent: React.FC<{ errorType: string }> = ({ errorType }) => {
    switch (errorType) {
        case 'string':
            throw 'String error';
        case 'null':
            throw null;
        case 'undefined':
            throw undefined;
        case 'object':
            throw { message: 'Object error' };
        case 'async':
            React.useEffect(() => {
                setTimeout(() => {
                    throw new Error('Async error');
                }, 100);
            }, []);
            return <div>Async component</div>;
        default:
            throw new Error('Default error');
    }
};

// Component with nested error boundaries
const NestedErrorComponent: React.FC = () => {
    return (
        <ErrorBoundary fallback={<div data-testid="outer-fallback">Outer fallback</div>}>
            <div>
                <ErrorBoundary fallback={<div data-testid="inner-fallback">Inner fallback</div>}>
                    <ErrorThrowingComponent />
                </ErrorBoundary>
            </div>
        </ErrorBoundary>
    );
};

// Component that errors in event handlers
const EventHandlerErrorComponent: React.FC = () => {
    const handleClick = () => {
        throw new Error('Event handler error');
    };

    return (
        <button data-testid="error-button" onClick={handleClick}>
            Click me
        </button>
    );
};

// Component that errors in useEffect
const UseEffectErrorComponent: React.FC = () => {
    React.useEffect(() => {
        throw new Error('useEffect error');
    }, []);

    return <div data-testid="useeffect-component">useEffect component</div>;
};

// Component that errors during render phase
const RenderErrorComponent: React.FC<{ phase: 'constructor' | 'render' | 'commit' }> = ({ phase }) => {
    if (phase === 'render') {
        throw new Error('Render phase error');
    }

    return <div data-testid="render-component">Render component</div>;
};

describe('Error Boundary Coverage Gaps', () => {
    describe('Basic Error Boundary Functionality', () => {
        test('should catch and display fallback for component errors', () => {
            render(
                <ErrorBoundary>
                    <ErrorThrowingComponent />
                </ErrorBoundary>
            );

            expect(screen.getByText('Something went wrong')).toBeInTheDocument();
            expect(screen.getByText('Reload Page')).toBeInTheDocument();
            expect(screen.getByText('Try Again')).toBeInTheDocument();
        });

        test('should render children normally when no error occurs', () => {
            render(
                <ErrorBoundary>
                    <ErrorThrowingComponent shouldThrow={false} />
                </ErrorBoundary>
            );

            expect(screen.getByTestId('normal-component')).toBeInTheDocument();
            expect(screen.queryByText('Something went wrong')).not.toBeInTheDocument();
        });

        test('should handle custom fallback UI', () => {
            const customFallback = <div data-testid="custom-fallback">Custom error message</div>;

            render(
                <ErrorBoundary fallback={customFallback}>
                    <ErrorThrowingComponent />
                </ErrorBoundary>
            );

            expect(screen.getByTestId('custom-fallback')).toBeInTheDocument();
            expect(screen.queryByText('Something went wrong')).not.toBeInTheDocument();
        });
    });

    describe('Different Error Types Handling', () => {
        test('should handle string errors', () => {
            render(
                <ErrorBoundary>
                    <DifferentErrorTypesComponent errorType="string" />
                </ErrorBoundary>
            );

            expect(screen.getByText('Something went wrong')).toBeInTheDocument();
        });

        test('should handle null errors', () => {
            render(
                <ErrorBoundary>
                    <DifferentErrorTypesComponent errorType="null" />
                </ErrorBoundary>
            );

            expect(screen.getByText('Something went wrong')).toBeInTheDocument();
        });

        test('should handle undefined errors', () => {
            render(
                <ErrorBoundary>
                    <DifferentErrorTypesComponent errorType="undefined" />
                </ErrorBoundary>
            );

            expect(screen.getByText('Something went wrong')).toBeInTheDocument();
        });

        test('should handle object errors', () => {
            render(
                <ErrorBoundary>
                    <DifferentErrorTypesComponent errorType="object" />
                </ErrorBoundary>
            );

            expect(screen.getByText('Something went wrong')).toBeInTheDocument();
        });
    });

    describe('Nested Error Boundaries', () => {
        test('should handle nested error boundaries correctly', () => {
            render(<NestedErrorComponent />);

            // Inner boundary should catch the error
            expect(screen.getByTestId('inner-fallback')).toBeInTheDocument();
            expect(screen.queryByTestId('outer-fallback')).not.toBeInTheDocument();
        });

        test('should isolate errors to the correct boundary level', () => {
            // Test with error in outer component but inner boundary should not catch it
            const OuterErrorComponent = () => {
                return (
                    <ErrorBoundary fallback={<div data-testid="outer-fallback">Outer fallback</div>}>
                        <ErrorBoundary fallback={<div data-testid="inner-fallback">Inner fallback</div>}>
                            <div>No error here</div>
                        </ErrorBoundary>
                        <ErrorThrowingComponent />
                    </ErrorBoundary>
                );
            };

            render(<OuterErrorComponent />);

            expect(screen.getByTestId('outer-fallback')).toBeInTheDocument();
            expect(screen.queryByTestId('inner-fallback')).not.toBeInTheDocument();
        });
    });

    describe('Error Recovery Mechanisms', () => {
        test('should allow retry after error', () => {
            render(
                <ErrorBoundary>
                    <ErrorThrowingComponent shouldThrow={true} />
                </ErrorBoundary>
            );

            expect(screen.getByText('Something went wrong')).toBeInTheDocument();

            // Click try again - this should reset the error boundary state
            fireEvent.click(screen.getByText('Try Again'));

            // The error boundary should reset, but the component will throw again
            // This tests that the retry mechanism works (resets state)
            // In a real scenario, the parent would provide different props or a different component
            expect(screen.getByText('Something went wrong')).toBeInTheDocument();
        });

        test('should handle reload page action', () => {
            // Mock window.location.reload
            const reloadMock = jest.fn();
            Object.defineProperty(window, 'location', {
                value: { reload: reloadMock },
                writable: true
            });

            render(
                <ErrorBoundary>
                    <ErrorThrowingComponent />
                </ErrorBoundary>
            );

            fireEvent.click(screen.getByText('Reload Page'));
            expect(reloadMock).toHaveBeenCalled();
        });
    });

    describe.skip('Error Boundary Coverage Gaps', () => {
        test('should document uncovered error scenarios', () => {
            // This test documents areas where error boundaries might not catch errors

            // 1. Errors in event handlers (not caught by error boundaries)
            render(
                <ErrorBoundary>
                    <EventHandlerErrorComponent />
                </ErrorBoundary>
            );

            // Click the button - this error won't be caught by the boundary
            expect(() => {
                fireEvent.click(screen.getByTestId('error-button'));
            }).toThrow('Event handler error');

            // Error boundary fallback should not appear
            expect(screen.queryByText('Something went wrong')).not.toBeInTheDocument();
        });

        test('should document async error handling gaps', () => {
            // Errors in setTimeout, promises, etc. are not caught by error boundaries
            const AsyncErrorComponent = () => {
                React.useEffect(() => {
                    setTimeout(() => {
                        throw new Error('Async error - not caught by boundary');
                    }, 100);
                }, []);
                return <div data-testid="async-component">Async component</div>;
            };

            render(
                <ErrorBoundary>
                    <AsyncErrorComponent />
                </ErrorBoundary>
            );

            // Component renders normally initially
            expect(screen.getByTestId('async-component')).toBeInTheDocument();

            // But async error won't be caught by error boundary
            // This is a known limitation of React error boundaries
        });

        test('should document useEffect error handling', () => {
            // useEffect errors during mount are caught
            expect(() => {
                render(
                    <ErrorBoundary>
                        <UseEffectErrorComponent />
                    </ErrorBoundary>
                );
            }).toThrow('useEffect error');

            // But the error boundary won't catch it in this test environment
            // In real React, this would be caught
        });
    });

    describe('Error Context and Information', () => {
        test('should provide error context in development', () => {
            // Mock process.env.NODE_ENV using Object.defineProperty
            const originalEnv = process.env.NODE_ENV;
            Object.defineProperty(process.env, 'NODE_ENV', {
                value: 'development',
                writable: true
            });

            render(
                <ErrorBoundary>
                    <ErrorThrowingComponent />
                </ErrorBoundary>
            );

            // In development, error details should be shown
            expect(screen.getByText('Something went wrong')).toBeInTheDocument();

            // Restore original env
            Object.defineProperty(process.env, 'NODE_ENV', {
                value: originalEnv,
                writable: true
            });
        });

        test('should hide error details in production', () => {
            // Mock process.env.NODE_ENV using Object.defineProperty
            const originalEnv = process.env.NODE_ENV;
            Object.defineProperty(process.env, 'NODE_ENV', {
                value: 'production',
                writable: true
            });

            render(
                <ErrorBoundary>
                    <ErrorThrowingComponent />
                </ErrorBoundary>
            );

            expect(screen.getByText('Something went wrong')).toBeInTheDocument();
            // Error details should be hidden in production

            // Restore original env
            Object.defineProperty(process.env, 'NODE_ENV', {
                value: originalEnv,
                writable: true
            });
        });
    });

    describe.skip('Error Boundary Performance', () => {
        test('should handle rapid error occurrences', () => {
            const RapidErrorComponent = ({ count }: { count: number }) => {
                if (count > 0) {
                    throw new Error(`Rapid error ${count}`);
                }
                return <div data-testid="rapid-component">Normal</div>;
            };

            const { rerender } = render(
                <ErrorBoundary>
                    <RapidErrorComponent count={1} />
                </ErrorBoundary>
            );

            expect(screen.getByText('Something went wrong')).toBeInTheDocument();

            // Try rendering with different error counts rapidly
            rerender(
                <ErrorBoundary>
                    <RapidErrorComponent count={2} />
                </ErrorBoundary>
            );

            // Should still show fallback
            expect(screen.getByText('Something went wrong')).toBeInTheDocument();
        });

        test('should handle error boundary re-mounting', () => {
            const { unmount, rerender } = render(
                <ErrorBoundary>
                    <ErrorThrowingComponent />
                </ErrorBoundary>
            );

            expect(screen.getByText('Something went wrong')).toBeInTheDocument();

            // Unmount and remount
            unmount();

            rerender(
                <ErrorBoundary>
                    <ErrorThrowingComponent shouldThrow={false} />
                </ErrorBoundary>
            );

            expect(screen.getByTestId('normal-component')).toBeInTheDocument();
        });
    });

    describe.skip('Integration with Other Components', () => {
        test('should work with React Router or navigation', () => {
            // This documents how error boundaries work with routing
            const RoutedComponent = ({ hasError }: { hasError: boolean }) => {
                if (hasError) {
                    throw new Error('Routing error');
                }
                return <div data-testid="routed-component">Routed content</div>;
            };

            const { rerender } = render(
                <ErrorBoundary>
                    <RoutedComponent hasError={true} />
                </ErrorBoundary>
            );

            expect(screen.getByText('Something went wrong')).toBeInTheDocument();

            // Simulate navigation (changing route)
            rerender(
                <ErrorBoundary>
                    <RoutedComponent hasError={false} />
                </ErrorBoundary>
            );

            expect(screen.getByTestId('routed-component')).toBeInTheDocument();
        });

        test('should handle errors in component lifecycle', () => {
            const LifecycleErrorComponent = () => {
                React.useEffect(() => {
                    // Simulate error in cleanup
                    return () => {
                        throw new Error('Cleanup error');
                    };
                }, []);

                throw new Error('Mount error');
            };

            expect(() => {
                render(
                    <ErrorBoundary>
                        <LifecycleErrorComponent />
                    </ErrorBoundary>
                );
            }).toThrow('Mount error');
        });
    });
});